<mujoco model="right_shadow_hand">
    <compiler angle="radian" coordinate="local" meshdir="../assets/mujoco_menagerie" autolimits="true"/>

    <option timestep="0.002" iterations="20" apirate="200">
        <flag warmstart="enable"/>
    </option>
    {#  <option impratio="10"/>#}

    <default>
        <default class="D_Touch">
            <site type="box" size="0.009 0.004 0.013" pos="0 -0.004 0.018" rgba="0.8 0.8 0.8 0.15" group="4"/>
        </default>
        <default class="DC_Hand">
            <geom material="MatColl" contype="1" conaffinity="0" group="4"/>
        </default>
        <default class="D_Vizual">
            <geom material="MatViz" contype="0" conaffinity="0" group="1" type="mesh"/>
        </default>
        <default class="free">
            <joint type="free" damping="0" armature="0" limited="false"/>
        </default>

        <default class="right_hand">
            <mesh scale="0.001 0.001 0.001"/>
            <joint limited="true" axis="1 0 0" damping="0.05" armature="0.001" margin="0.01" frictionloss="0.001"/>
            <position forcerange="-1 1"/>
            <geom friction="1 0.005 0.001" condim="3" margin="0.0005" contype="1" conaffinity="1"/>
            <site size="0.005" rgba="0.4 0.9 0.4 1"/>
            <general ctrllimited="true" forcelimited="true"/>

            <default class="wrist">
                <joint damping="0.5"/>
                <default class="wrist_y">
                    <joint axis="0 1 0" range="-0.523599 0.174533"/>
                    <position kp="5" ctrlrange="-0.523599 0.174533" forcerange="-4.785 4.785"/>
                </default>
                <default class="wrist_x">
                    <joint range="-0.698132 0.488692"/>
                    <position kp="5" ctrlrange="-0.698132 0.488692" forcerange="-2.175 2.175"/>
                </default>
            </default>

            <default class="thumb">
                <default class="thbase">
                    <joint axis="0 0 -1" range="-1.0472 1.0472"/>
                    <position kp="1" ctrlrange="-1.0472 1.0472" forcerange="-2.3722 2.3722"/>
                </default>
                <default class="thproximal">
                    <joint range="0 1.22173"/>
                    <position ctrlrange="0 1.22173" forcerange="-1.45 1.45"/>
                </default>
                <default class="thhub">
                    <joint range="-0.20944 0.20944"/>
                    <position kp="1" ctrlrange="-0.20944 0.20944" forcerange="-0.99 0.99"/>
                </default>
                <default class="thmiddle">
                    <joint axis="0 -1 0" range="-0.698132 0.698132"/>
                    <position kp="1" ctrlrange="-0.698132 0.698132" forcerange="-0.99 0.99"/>
                </default>
                <default class="thdistal">
                    <joint range="-0.261799 1.5708"/>
                    <position ctrlrange="-0.261799 1.5708" forcerange="-0.81 0.81"/>
                </default>
            </default>

            <default class="metacarpal">
                <joint axis="0.573576 0 0.819152" range="0 0.785398"/>
                <position ctrlrange="0 0.785398" forcerange="-0.9 0.9"/>
            </default>
            <default class="knuckle">
                <joint axis="0 -1 0" range="-0.349066 0.349066"/>
                <position ctrlrange="-0.349066 0.349066" forcerange="-0.9 0.9"/>
            </default>
            <default class="proximal">
                <joint range="-0.261799 1.5708"/>
                <position ctrlrange="-0.261799 1.5708" forcerange="-0.9 0.9"/>
            </default>
            <default class="middle_distal">
                <joint range="0 1.5708"/>
                <position kp="1" ctrlrange="0 3.1415" forcerange="-0.9 0.9"/>
            </default>

            <default class="plastic">
                <geom solimp="0.5 0.99 0.0001" solref="0.005 1"/>
                <default class="plastic_visual">
                    <geom type="mesh" material="black" contype="0" conaffinity="0" group="2"/>
                </default>
                <default class="plastic_collision">
                    <geom group="3"/>
                </default>
            </default>
        </default>
    </default>

    <asset>
        <material name="black" specular="0.5" shininess="0.25" rgba="0.16355 0.16355 0.16355 1"/>
        <material name="gray" specular="0.0" shininess="0.25" rgba="0.80848 0.80848 0.80848 1"/>
        <material name="metallic" specular="0" shininess="0.25" rgba="0.9 0.9 0.9 1"/>

        <mesh class="right_hand" file="forearm_0.obj"/>
        <mesh class="right_hand" file="forearm_1.obj"/>
        <mesh class="right_hand" file="forearm_collision.obj"/>
        <mesh class="right_hand" file="wrist.obj"/>
        <mesh class="right_hand" file="palm.obj"/>
        <mesh class="right_hand" file="f_knuckle.obj"/>
        <mesh class="right_hand" file="f_proximal.obj"/>
        <mesh class="right_hand" file="f_middle.obj"/>
        <mesh class="right_hand" file="f_distal_pst.obj"/>
        <mesh class="right_hand" file="lf_metacarpal.obj"/>
        <mesh class="right_hand" file="th_proximal.obj"/>
        <mesh class="right_hand" file="th_middle.obj"/>
        <mesh class="right_hand" file="th_distal_pst.obj"/>
    </asset>

    <worldbody>
        <body name="rh_forearm" childclass="right_hand" quat="1 -1 1 -1">
            <inertial mass="3" pos="0 0 0.09" diaginertia="0.0138 0.0138 0.00744"/>
            <geom class="plastic_visual" mesh="forearm_0" material="gray"/>
            <geom class="plastic_visual" mesh="forearm_1"/>
            <geom class="plastic_collision" type="mesh" mesh="forearm_collision"/>
            <geom class="plastic_collision" size="0.035 0.035 0.035" pos="0 -0.01 0.181" quat="0.924909 0 0.380188 0"
                  type="box"/>
            <body name="rh_wrist" pos="0 -0.01 0.21301">
                <inertial mass="0.1" pos="0 0 0.029" quat="0.5 0.5 0.5 0.5" diaginertia="6.4e-05 4.38e-05 3.5e-05"/>
                <joint class="wrist_y" name="rh_WRJ2"/>
                <geom class="plastic_visual" mesh="wrist" material="metallic"/>
                <geom size="0.0135 0.015" quat="0.499998 0.5 0.5 -0.500002" type="cylinder" class="plastic_collision"/>
                <geom size="0.011 0.005" pos="-0.026 0 0.034" quat="1 0 1 0" type="cylinder" class="plastic_collision"/>
                <geom size="0.011 0.005" pos="0.031 0 0.034" quat="1 0 1 0" type="cylinder" class="plastic_collision"/>
                <geom size="0.0135 0.009 0.005" pos="-0.021 0 0.011" quat="0.923879 0 0.382684 0" type="box"
                      class="plastic_collision"/>
                <geom size="0.0135 0.009 0.005" pos="0.026 0 0.01" quat="0.923879 0 -0.382684 0" type="box"
                      class="plastic_collision"/>
                <body name="rh_palm" pos="0 0 0.034">
                    <inertial mass="0.3" pos="0 0 0.035" quat="1 0 0 1" diaginertia="0.0005287 0.0003581 0.000191"/>
                    <joint class="wrist_x" name="rh_WRJ1"/>
                    <site name="grasp_site" pos="0 -.035 0.09" group="4"/>
                    <site name="palm_center_site" pos="0 .0 0.05" group="4" rgba="0 0 0 1"/>
                    <geom class="plastic_visual" mesh="palm"/>
                    <geom size="0.031 0.0035 0.049" pos="0.011 0.0085 0.038" type="box" class="plastic_collision"/>
                    <geom size="0.018 0.0085 0.049" pos="-0.002 -0.0035 0.038" type="box" class="plastic_collision"/>
                    <geom size="0.013 0.0085 0.005" pos="0.029 -0.0035 0.082" type="box" class="plastic_collision"/>
                    <geom size="0.013 0.007 0.009" pos="0.0265 -0.001 0.07" quat="0.987241 0.0990545 0.0124467 0.124052"
                          type="box" class="plastic_collision"/>
                    <geom size="0.0105 0.0135 0.012" pos="0.0315 -0.0085 0.001" type="box" class="plastic_collision"/>
                    <geom size="0.011 0.0025 0.015" pos="0.0125 -0.015 0.004" quat="0.971338 0 0 -0.237703" type="box"
                          class="plastic_collision"/>
                    <geom size="0.009 0.012 0.002" pos="0.011 0 0.089" type="box" class="plastic_collision"/>
                    <geom size="0.01 0.012 0.02" pos="-0.03 0 0.009" type="box" class="plastic_collision"/>

                    <!-- AngoraPy Edit: Touch Sensors -->
                    <site name="T_palm_b0" type="box" group="5" pos="0.011 -0.005 0.006" size="0.033 0.007 0.019"
                          rgba="0 0 0 0"/>
                    <site name="T_palm_bl" type="box" group="5" pos="-0.011 -0.005 0.041" size="0.011 0.007 0.016"
                          rgba="1 0 0 0"/>
                    <site name="T_palm_bm" type="box" group="5" pos="0.011 -0.005 0.041" size="0.011 0.007 0.016"
                          rgba="0 0 0 0"/>
                    <site name="T_palm_br" type="box" group="5" pos="0.033 -0.005 0.041" size="0.011 0.007 0.016"
                          rgba="1 0 0 0"/>
                    <site name="T_palm_fl" type="box" group="5" pos="-0.011 -0.005 0.073" size="0.011 0.007 0.016"
                          rgba="0 0 0 0"/>
                    <site name="T_palm_fm" type="box" group="5" pos="0.011 -0.005 0.073" size="0.011 0.007 0.016"
                          rgba="1 0 0 0"/>
                    <site name="T_palm_fr" type="box" group="5" pos="0.033 -0.005 0.073" size="0.011 0.007 0.016"
                          rgba="0 0 0 0"/>
                    <site name="T_palm_b1" type="box" group="5" pos="-0.0325 -0.005 0.014" size="0.012 0.007 0.027"
                          rgba="0 0 0 0"/>
                    <body name="rh_ffknuckle" pos="0.033 0 0.095">
                        <inertial mass="0.008" pos="0 0 0" quat="0.5 0.5 -0.5 0.5"
                                  diaginertia="3.2e-07 2.6e-07 2.6e-07"/>
                        <joint name="rh_FFJ4" class="knuckle"/>
                        <geom pos="0 0 0.0005" class="plastic_visual" mesh="f_knuckle" material="metallic"/>
                        <geom size="0.009 0.009" quat="1 0 1 0" type="cylinder" class="plastic_collision"/>
                        <body name="rh_ffproximal">
                            <inertial mass="0.03" pos="0 0 0.0225" quat="1 0 0 1" diaginertia="1e-05 9.8e-06 1.8e-06"/>
                            <joint name="rh_FFJ3" class="proximal"/>
                            <geom class="plastic_visual" mesh="f_proximal"/>
                            <geom size="0.009 0.02" pos="0 0 0.025" type="capsule" class="plastic_collision"/>

                            <!-- AngoraPy Edit: Touch Sensors -->
                            <site name="T_ffproximal_front_left_bottom" type="box" group="5" pos="-0.005 -0.005 0.00625"
                                  size="0.005 0.005 0.01625" rgba="1 0 0 0"/>
                            <site name="T_ffproximal_front_right_bottom" type="box" group="5" pos="0.005 -0.005 0.00625"
                                  size="0.005 0.005 0.01625" rgba="0 0 0 0"/>
                            <site name="T_ffproximal_front_left_top" type="box" group="5" pos="-0.005 -0.005 0.03875"
                                  size="0.005 0.005 0.01625" rgba="0 0 0 0"/>
                            <site name="T_ffproximal_front_right_top" type="box" group="5" pos="0.005 -0.005 0.03875"
                                  size="0.005 0.005 0.01625" rgba="1 0 0 0"/>
                            <site name="T_ffproximal_back_left" type="box" group="5" pos="-0.005 0.005 0.0225"
                                  size="0.005 0.005 0.0325"
                                  rgba="0 0 0 0"/>
                            <site name="T_ffproximal_back_right" type="box" group="5" pos="0.005 0.005 0.0225"
                                  size="0.005 0.005 0.0325"
                                  rgba="1 0 0 0"/>
                            <site name="T_ffproximal_tip" type="sphere" group="5" pos="0 0 0.045" size="0.011"
                                  rgba="1 1 0 0"/>

                            <body name="rh_ffmiddle" pos="0 0 0.045">
                                <inertial mass="0.017" pos="0 0 0.0125" quat="1 0 0 1"
                                          diaginertia="2.7e-06 2.6e-06 8.7e-07"/>
                                <joint name="rh_FFJ2" class="middle_distal"/>
                                <geom class="plastic_visual" mesh="f_middle"/>
                                <geom size="0.009 0.0125" pos="0 0 0.0125" type="capsule" class="plastic_collision"/>

                                <!-- AngoraPy Edit: Touch Sensors -->
                                <site name="T_ffmiddle_front_left" type="box" group="5" pos="-0.00451 -0.00451 0.0125"
                                      size="0.00451 0.00451 0.02055" rgba="0 0 0 0"/>
                                <site name="T_ffmiddle_front_right" type="box" group="5" pos="0.00451 -0.00451 0.0125"
                                      size="0.00451 0.00451 0.02055" rgba="1 0 0 0"/>
                                <site name="T_ffmiddle_back_left" type="box" group="5" pos="-0.00451 0.00451 0.0125"
                                      size="0.00451 0.00451 0.02055" rgba="1 0 0 0"/>
                                <site name="T_ffmiddle_back_right" type="box" group="5" pos="0.00451 0.00451 0.0125"
                                      size="0.00451 0.00451 0.02055" rgba="0 0 0 0"/>
                                <site name="T_ffmiddle_tip" type="sphere" group="5" pos="0 0 0.025" size="0.009"
                                      rgba="1 1 0 0"/>

                                <body name="rh_ffdistal" pos="0 0 0.025">
                                    <inertial mass="0.013" pos="0 0 0.0130769" quat="1 0 0 1"
                                              diaginertia="1.28092e-06 1.12092e-06 5.3e-07"/>
                                    <joint name="rh_FFJ1" class="middle_distal"/>
                                    <geom class="plastic_visual" mesh="f_distal_pst"/>
                                    <geom class="plastic_collision" type="mesh" mesh="f_distal_pst"/>
                                    <!-- AngoraPy Edit: Touch Sensors -->
                                    <site name="rh_S_fftip" pos="0 0 0.026" group="3"/>
                                    <site class="D_Touch" name="Tch_fftip"/>
                                    <site name="T_fftip_front_left" type="box" group="5" pos="-0.00451 -0.00451 0.012"
                                          size="0.00451 0.00451 0.01905" rgba="1 0 0 0"/>
                                    <site name="T_fftip_front_right" type="box" group="5" pos="0.00451 -0.00451 0.012"
                                          size="0.00451 0.00451 0.01905" rgba="0 0 0 0"/>
                                    <site name="T_fftip_back_left" type="box" group="5" pos="-0.00451 0.00451 0.012"
                                          size="0.00451 0.00451 0.01905"
                                          rgba="0 0 0 0"/>
                                    <site name="T_fftip_back_right" type="box" group="5" pos="0.00451 0.00451 0.012"
                                          size="0.00451 0.00451 0.01905"
                                          rgba="1 0 0 0"/>
                                    <site name="T_fftip_tip" type="sphere" group="5" pos="0 0 0.024" size="0.008"
                                          rgba="1 1 0 0"/>

                                </body>
                            </body>
                        </body>
                    </body>
                    <body name="rh_mfknuckle" pos="0.011 0 0.099">
                        <inertial mass="0.008" pos="0 0 0" quat="0.5 0.5 -0.5 0.5"
                                  diaginertia="3.2e-07 2.6e-07 2.6e-07"/>
                        <joint name="rh_MFJ4" class="knuckle"/>
                        <geom pos="0 0 0.0005" class="plastic_visual" mesh="f_knuckle" material="metallic"/>
                        <geom size="0.009 0.009" quat="1 0 1 0" type="cylinder" class="plastic_collision"/>
                        <body name="rh_mfproximal">
                            <inertial mass="0.03" pos="0 0 0.0225" quat="1 0 0 1" diaginertia="1e-05 9.8e-06 1.8e-06"/>
                            <joint name="rh_MFJ3" class="proximal"/>
                            <geom class="plastic_visual" mesh="f_proximal"/>
                            <geom size="0.009 0.02" pos="0 0 0.025" type="capsule" class="plastic_collision"/>

                            <!-- AngoraPy Edit: Touch Sensors -->
                            <site name="T_mfproximal_front_left_bottom" type="box" group="5" pos="-0.005 -0.005 0.00625"
                                  size="0.005 0.005 0.01625" rgba="1 0 0 0"/>
                            <site name="T_mfproximal_front_right_bottom" type="box" group="5" pos="0.005 -0.005 0.00625"
                                  size="0.005 0.005 0.01625" rgba="0 0 0 0"/>
                            <site name="T_mfproximal_front_left_top" type="box" group="5" pos="-0.005 -0.005 0.03875"
                                  size="0.005 0.005 0.01625" rgba="0 0 0 0"/>
                            <site name="T_mfproximal_front_right_top" type="box" group="5" pos="0.005 -0.005 0.03875"
                                  size="0.005 0.005 0.01625" rgba="1 0 0 0"/>
                            <site name="T_mfproximal_back_left" type="box" group="5" pos="-0.005 0.005 0.0225"
                                  size="0.005 0.005 0.0325"
                                  rgba="0 0 0 0"/>
                            <site name="T_mfproximal_back_right" type="box" group="5" pos="0.005 0.005 0.0225"
                                  size="0.005 0.005 0.0325"
                                  rgba="1 0 0 0"/>
                            <site name="T_mfproximal_tip" type="sphere" group="5" pos="0 0 0.045" size="0.011"
                                  rgba="1 1 0 0"/>
                            <body name="rh_mfmiddle" pos="0 0 0.045">
                                <inertial mass="0.017" pos="0 0 0.0125" quat="1 0 0 1"
                                          diaginertia="2.7e-06 2.6e-06 8.7e-07"/>
                                <joint name="rh_MFJ2" class="middle_distal"/>
                                <geom class="plastic_visual" mesh="f_middle"/>
                                <geom size="0.009 0.0125" pos="0 0 0.0125" type="capsule" class="plastic_collision"/>

                                <!-- AngoraPy Edit: Touch Sensors -->
                                <site name="T_mfmiddle_front_left" type="box" group="5" pos="-0.00451 -0.00451 0.0125"
                                      size="0.00451 0.00451 0.02055" rgba="0 0 0 0"/>
                                <site name="T_mfmiddle_front_right" type="box" group="5" pos="0.00451 -0.00451 0.0125"
                                      size="0.00451 0.00451 0.02055" rgba="1 0 0 0"/>
                                <site name="T_mfmiddle_back_left" type="box" group="5" pos="-0.00451 0.00451 0.0125"
                                      size="0.00451 0.00451 0.02055" rgba="1 0 0 0"/>
                                <site name="T_mfmiddle_back_right" type="box" group="5" pos="0.00451 0.00451 0.0125"
                                      size="0.00451 0.00451 0.02055" rgba="0 0 0 0"/>
                                <site name="T_mfmiddle_tip" type="sphere" group="5" pos="0 0 0.025" size="0.009"
                                      rgba="1 1 0 0"/>

                                <body name="rh_mfdistal" pos="0 0 0.025">
                                    <inertial mass="0.013" pos="0 0 0.0130769" quat="1 0 0 1"
                                              diaginertia="1.28092e-06 1.12092e-06 5.3e-07"/>
                                    <joint name="rh_MFJ1" class="middle_distal"/>
                                    <geom class="plastic_visual" mesh="f_distal_pst"/>
                                    <geom class="plastic_collision" type="mesh" mesh="f_distal_pst"/>

                                    <!-- AngoraPy Edit: Touch Sensors -->
                                    <site name="rh_S_mftip" pos="0 0 0.026" group="3"/>
                                    <site class="D_Touch" name="Tch_mftip"/>
                                    <site name="T_mftip_front_left" type="box" group="5" pos="-0.00451 -0.00451 0.012"
                                          size="0.00451 0.00451 0.01905" rgba="1 0 0 0"/>
                                    <site name="T_mftip_front_right" type="box" group="5" pos="0.00451 -0.00451 0.012"
                                          size="0.00451 0.00451 0.01905" rgba="0 0 0 0"/>
                                    <site name="T_mftip_back_left" type="box" group="5" pos="-0.00451 0.00451 0.012"
                                          size="0.00451 0.00451 0.01905"
                                          rgba="0 0 0 0"/>
                                    <site name="T_mftip_back_right" type="box" group="5" pos="0.00451 0.00451 0.012"
                                          size="0.00451 0.00451 0.01905"
                                          rgba="1 0 0 0"/>
                                    <site name="T_mftip_tip" type="sphere" group="5" pos="0 0 0.024" size="0.008"
                                          rgba="1 1 0 0"/>
                                </body>
                            </body>
                        </body>
                    </body>
                    <body name="rh_rfknuckle" pos="-0.011 0 0.095">
                        <inertial mass="0.008" pos="0 0 0" quat="0.5 0.5 -0.5 0.5"
                                  diaginertia="3.2e-07 2.6e-07 2.6e-07"/>
                        <joint name="rh_RFJ4" class="knuckle" axis="0 1 0"/>
                        <geom pos="0 0 0.0005" class="plastic_visual" mesh="f_knuckle" material="metallic"/>
                        <geom size="0.009 0.009" quat="1 0 1 0" type="cylinder" class="plastic_collision"/>
                        <body name="rh_rfproximal">
                            <inertial mass="0.03" pos="0 0 0.0225" quat="1 0 0 1" diaginertia="1e-05 9.8e-06 1.8e-06"/>
                            <joint name="rh_RFJ3" class="proximal"/>
                            <geom class="plastic_visual" mesh="f_proximal"/>
                            <geom size="0.009 0.02" pos="0 0 0.025" type="capsule" class="plastic_collision"/>

                            <!-- AngoraPy Edit: Touch Sensors -->
                            <site name="T_rfproximal_front_left_bottom" type="box" group="5" pos="-0.005 -0.005 0.00625"
                                  size="0.005 0.005 0.01625" rgba="1 0 0 0"/>
                            <site name="T_rfproximal_front_right_bottom" type="box" group="5" pos="0.005 -0.005 0.00625"
                                  size="0.005 0.005 0.01625" rgba="0 0 0 0"/>
                            <site name="T_rfproximal_front_left_top" type="box" group="5" pos="-0.005 -0.005 0.03875"
                                  size="0.005 0.005 0.01625" rgba="0 0 0 0"/>
                            <site name="T_rfproximal_front_right_top" type="box" group="5" pos="0.005 -0.005 0.03875"
                                  size="0.005 0.005 0.01625" rgba="1 0 0 0"/>
                            <site name="T_rfproximal_back_left" type="box" group="5" pos="-0.005 0.005 0.0225"
                                  size="0.005 0.005 0.0325"
                                  rgba="0 0 0 0"/>
                            <site name="T_rfproximal_back_right" type="box" group="5" pos="0.005 0.005 0.0225"
                                  size="0.005 0.005 0.0325"
                                  rgba="1 0 0 0"/>
                            <site name="T_rfproximal_tip" type="sphere" group="5" pos="0 0 0.045" size="0.011"
                                  rgba="1 1 0 0"/>
                            <body name="rh_rfmiddle" pos="0 0 0.045">
                                <inertial mass="0.017" pos="0 0 0.0125" quat="1 0 0 1"
                                          diaginertia="2.7e-06 2.6e-06 8.7e-07"/>
                                <joint name="rh_RFJ2" class="middle_distal"/>
                                <geom class="plastic_visual" mesh="f_middle"/>
                                <geom size="0.009 0.0125" pos="0 0 0.0125" type="capsule" class="plastic_collision"/>

                                <!-- AngoraPy Edit: Touch Sensors -->
                                <site name="T_rfmiddle_front_left" type="box" group="5" pos="-0.00451 -0.00451 0.0125"
                                      size="0.00451 0.00451 0.02055" rgba="0 0 0 0"/>
                                <site name="T_rfmiddle_front_right" type="box" group="5" pos="0.00451 -0.00451 0.0125"
                                      size="0.00451 0.00451 0.02055" rgba="1 0 0 0"/>
                                <site name="T_rfmiddle_back_left" type="box" group="5" pos="-0.00451 0.00451 0.0125"
                                      size="0.00451 0.00451 0.02055" rgba="1 0 0 0"/>
                                <site name="T_rfmiddle_back_right" type="box" group="5" pos="0.00451 0.00451 0.0125"
                                      size="0.00451 0.00451 0.02055" rgba="0 0 0 0"/>
                                <site name="T_rfmiddle_tip" type="sphere" group="5" pos="0 0 0.025" size="0.009"
                                      rgba="1 1 0 0"/>

                                <body name="rh_rfdistal" pos="0 0 0.025">
                                    <inertial mass="0.013" pos="0 0 0.0130769" quat="1 0 0 1"
                                              diaginertia="1.28092e-06 1.12092e-06 5.3e-07"/>
                                    <joint name="rh_RFJ1" class="middle_distal"/>
                                    <geom class="plastic_visual" mesh="f_distal_pst"/>
                                    <geom class="plastic_collision" type="mesh" mesh="f_distal_pst"/>

                                    <!-- AngoraPy Edit: Touch Sensors -->
                                    <site name="rh_S_rftip" pos="0 0 0.026" group="3"/>
                                    <site class="D_Touch" name="Tch_rftip"/>
                                    <site name="T_rftip_front_left" type="box" group="5" pos="-0.00451 -0.00451 0.012"
                                          size="0.00451 0.00451 0.01905" rgba="1 0 0 0"/>
                                    <site name="T_rftip_front_right" type="box" group="5" pos="0.00451 -0.00451 0.012"
                                          size="0.00451 0.00451 0.01905" rgba="0 0 0 0"/>
                                    <site name="T_rftip_back_left" type="box" group="5" pos="-0.00451 0.00451 0.012"
                                          size="0.00451 0.00451 0.01905"
                                          rgba="0 0 0 0"/>
                                    <site name="T_rftip_back_right" type="box" group="5" pos="0.00451 0.00451 0.012"
                                          size="0.00451 0.00451 0.01905"
                                          rgba="1 0 0 0"/>
                                    <site name="T_rftip_tip" type="sphere" group="5" pos="0 0 0.024" size="0.008"
                                          rgba="1 1 0 0"/>
                                </body>
                            </body>
                        </body>
                    </body>
                    <body name="rh_lfmetacarpal" pos="-0.033 0 0.02071">
                        <inertial mass="0.03" pos="0 0 0.04" quat="1 0 0 1" diaginertia="1.638e-05 1.45e-05 4.272e-06"/>
                        <joint name="rh_LFJ5" class="metacarpal"/>
                        <geom class="plastic_visual" mesh="lf_metacarpal"/>
                        <geom size="0.011 0.012 0.025" pos="0.002 0 0.033" type="box" class="plastic_collision"/>
                        <site name="T_lfmetacarpal_front" type="box" group="5" pos="-0.0165 -0.005 0.00975"
                              size="0.01 0.007 0.026"
                              rgba="1 0 0 0"/>
                        <body name="rh_lfknuckle" pos="0 0 0.06579">
                            <inertial mass="0.008" pos="0 0 0" quat="0.5 0.5 -0.5 0.5"
                                      diaginertia="3.2e-07 2.6e-07 2.6e-07"/>
                            <joint name="rh_LFJ4" class="knuckle" axis="0 1 0"/>
                            <geom pos="0 0 0.0005" class="plastic_visual" mesh="f_knuckle" material="metallic"/>
                            <geom size="0.009 0.009" quat="1 0 1 0" type="cylinder" class="plastic_collision"/>
                            <body name="rh_lfproximal">
                                <inertial mass="0.03" pos="0 0 0.0225" quat="1 0 0 1"
                                          diaginertia="1e-05 9.8e-06 1.8e-06"/>
                                <joint name="rh_LFJ3" class="proximal"/>
                                <geom class="plastic_visual" mesh="f_proximal"/>
                                <geom size="0.009 0.02" pos="0 0 0.025" type="capsule" class="plastic_collision"/>
                                <site name="T_lfproximal_front_left_bottom" type="box" group="5"
                                      pos="-0.005 -0.005 0.00625"
                                      size="0.005 0.005 0.01625" rgba="1 0 0 0"/>
                                <site name="T_lfproximal_front_right_bottom" type="box" group="5"
                                      pos="0.005 -0.005 0.00625"
                                      size="0.005 0.005 0.01625" rgba="0 0 0 0"/>
                                <site name="T_lfproximal_front_left_top" type="box" group="5"
                                      pos="-0.005 -0.005 0.03875"
                                      size="0.005 0.005 0.01625" rgba="0 0 0 0"/>
                                <site name="T_lfproximal_front_right_top" type="box" group="5"
                                      pos="0.005 -0.005 0.03875"
                                      size="0.005 0.005 0.01625" rgba="1 0 0 0"/>
                                <site name="T_lfproximal_back_left" type="box" group="5" pos="-0.005 0.005 0.0225"
                                      size="0.005 0.005 0.0325"
                                      rgba="0 0 0 0"/>
                                <site name="T_lfproximal_back_right" type="box" group="5" pos="0.005 0.005 0.0225"
                                      size="0.005 0.005 0.0325"
                                      rgba="1 0 0 0"/>
                                <site name="T_lfproximal_tip" type="sphere" group="5" pos="0 0 0.045" size="0.011"
                                      rgba="1 1 0 0"/>
                                <body name="rh_lfmiddle" pos="0 0 0.045">
                                    <inertial mass="0.017" pos="0 0 0.0125" quat="1 0 0 1"
                                              diaginertia="2.7e-06 2.6e-06 8.7e-07"/>
                                    <joint name="rh_LFJ2" class="middle_distal"/>
                                    <geom class="plastic_visual" mesh="f_middle"/>
                                    <geom size="0.009 0.0125" pos="0 0 0.0125" type="capsule"
                                          class="plastic_collision"/>
                                    <site name="T_lfmiddle_front_left" type="box" group="5"
                                          pos="-0.00451 -0.00451 0.0125"
                                          size="0.00451 0.00451 0.02055" rgba="0 0 0 0"/>
                                    <site name="T_lfmiddle_front_right" type="box" group="5"
                                          pos="0.00451 -0.00451 0.0125"
                                          size="0.00451 0.00451 0.02055" rgba="1 0 0 0"/>
                                    <site name="T_lfmiddle_back_left" type="box" group="5" pos="-0.00451 0.00451 0.0125"
                                          size="0.00451 0.00451 0.02055" rgba="1 0 0 0"/>
                                    <site name="T_lfmiddle_back_right" type="box" group="5" pos="0.00451 0.00451 0.0125"
                                          size="0.00451 0.00451 0.02055" rgba="0 0 0 0"/>
                                    <site name="T_lfmiddle_tip" type="sphere" group="5" pos="0 0 0.025" size="0.009"
                                          rgba="1 1 0 0"/>
                                    <body name="rh_lfdistal" pos="0 0 0.025">
                                        <inertial mass="0.013" pos="0 0 0.0130769" quat="1 0 0 1"
                                                  diaginertia="1.28092e-06 1.12092e-06 5.3e-07"/>
                                        <joint name="rh_LFJ1" class="middle_distal"/>
                                        <geom class="plastic_visual" mesh="f_distal_pst"/>
                                        <geom class="plastic_collision" type="mesh" mesh="f_distal_pst"/>

                                        <site name="rh_S_lftip" pos="0 0 0.026" group="3"/>
                                        <site class="D_Touch" name="Tch_lftip"/>
                                        <site name="T_lftip_front_left" type="box" group="5"
                                              pos="-0.00451 -0.00451 0.012"
                                              size="0.00451 0.00451 0.01905" rgba="1 0 0 0"/>
                                        <site name="T_lftip_front_right" type="box" group="5"
                                              pos="0.00451 -0.00451 0.012"
                                              size="0.00451 0.00451 0.01905" rgba="0 0 0 0"/>
                                        <site name="T_lftip_back_left" type="box" group="5" pos="-0.00451 0.00451 0.012"
                                              size="0.00451 0.00451 0.01905"
                                              rgba="0 0 0 0"/>
                                        <site name="T_lftip_back_right" type="box" group="5" pos="0.00451 0.00451 0.012"
                                              size="0.00451 0.00451 0.01905"
                                              rgba="1 0 0 0"/>
                                        <site name="T_lftip_tip" type="sphere" group="5" pos="0 0 0.024" size="0.008"
                                              rgba="1 1 0 0"/>
                                    </body>
                                </body>
                            </body>
                        </body>
                    </body>
                    <body name="rh_thbase" pos="0.034 -0.00858 0.029" quat="0.92388 0 0.382683 0">
                        <inertial mass="0.01" pos="0 0 0" diaginertia="1.6e-07 1.6e-07 1.6e-07"/>
                        <joint name="rh_THJ5" class="thbase"/>
                        <geom class="plastic_collision" size="0.013"/>
                        <body name="rh_thproximal">
                            <inertial mass="0.04" pos="0 0 0.019" diaginertia="1.36e-05 1.36e-05 3.13e-06"/>
                            <joint name="rh_THJ4" class="thproximal"/>
                            <geom class="plastic_visual" mesh="th_proximal"/>
                            <geom class="plastic_collision" size="0.0105 0.009" pos="0 0 0.02" type="capsule"/>

                            <site name="T_thproximal_front_left" type="box" group="5" pos="-0.007 -0.007 0.019"
                                  size="0.007 0.007 0.032"
                                  rgba="0 0 0 0"/>
                            <site name="T_thproximal_front_right" type="box" group="5" pos="0.007 -0.007 0.019"
                                  size="0.007 0.007 0.032"
                                  rgba="1 0 0 0"/>
                            <site name="T_thproximal_back_left" type="box" group="5" pos="-0.007 0.007 0.019"
                                  size="0.007 0.007 0.032"
                                  rgba="1 0 0 0"/>
                            <site name="T_thproximal_back_right" type="box" group="5" pos="0.007 0.007 0.019"
                                  size="0.007 0.007 0.032"
                                  rgba="0 0 0 0"/>
                            <site name="T_thproximal_tip" type="sphere" group="5" pos="0 0 0.038" size="0.014"
                                  rgba="1 1 0 0"/>

                            <body name="rh_thhub" pos="0 0 0.038">
                                <inertial mass="0.005" pos="0 0 0" diaginertia="1e-06 1e-06 3e-07"/>
                                <joint name="rh_THJ3" class="thhub"/>
                                <geom size="0.011" class="plastic_collision"/>
                                <body name="rh_thmiddle">
                                    <inertial mass="0.02" pos="0 0 0.016" diaginertia="5.1e-06 5.1e-06 1.21e-06"/>
                                    <joint name="rh_THJ2" class="thmiddle"/>
                                    <geom class="plastic_visual" mesh="th_middle"/>
                                    <geom size="0.009 0.009" pos="0 0 0.012" type="capsule" class="plastic_collision"/>
                                    <geom size="0.01" pos="0 0 0.03" class="plastic_collision"/>

                                    <site name="T_thmiddle_front_left" type="box" group="5" pos="-0.006 -0.006 0.016"
                                          size="0.006 0.006 0.027"
                                          rgba="1 0 0 0"/>
                                    <site name="T_thmiddle_front_right" type="box" group="5" pos="0.006 -0.006 0.016"
                                          size="0.006 0.006 0.027"
                                          rgba="0 0 0 0"/>
                                    <site name="T_thmiddle_back_left" type="box" group="5" pos="-0.006 0.006 0.016"
                                          size="0.006 0.006 0.027"
                                          rgba="0 0 0 0"/>
                                    <site name="T_thmiddle_back_right" type="box" group="5" pos="0.006 0.006 0.016"
                                          size="0.006 0.006 0.027"
                                          rgba="1 0 0 0"/>
                                    <site name="T_thmiddle_tip" type="sphere" group="5" pos="0 0 0.032" size="0.012"
                                          rgba="1 1 0 0"/>

                                    <body name="rh_thdistal" pos="0 0 0.032" quat="1 0 0 -1">
                                        <inertial mass="0.017" pos="0 0 0.0145588" quat="1 0 0 1"
                                                  diaginertia="2.37794e-06 2.27794e-06 1e-06"/>
                                        <joint name="rh_THJ1" class="thdistal"/>
                                        <geom class="plastic_visual" mesh="th_distal_pst"/>
                                        <geom class="plastic_collision" type="mesh" mesh="th_distal_pst"/>

                                        <site name="rh_S_thtip" pos="0 0 0.0275" group="3"/>
                                        <site class="D_Touch" name="Tch_thtip" size="0.005 0.011 0.016"
                                              pos="-0.005 0 0.02"/>
                                        <site name="T_thtip_front_left" type="box" group="5" pos="-0.0056 -0.0056 0.013"
                                              size="0.0056 0.0056 0.02218"
                                              rgba="0 0 0 0"/>
                                        <site name="T_thtip_front_right" type="box" group="5" pos="0.0056 -0.0056 0.013"
                                              size="0.0056 0.0056 0.02218"
                                              rgba="1 0 0 0"/>
                                        <site name="T_thtip_back_left" type="box" group="5" pos="-0.0056 0.0056 0.013"
                                              size="0.0056 0.0056 0.02218"
                                              rgba="1 0 0 0"/>
                                        <site name="T_thtip_back_right" type="box" group="5" pos="0.0056 0.0056 0.013"
                                              size="0.0056 0.0056 0.02218"
                                              rgba="0 0 0 0"/>
                                        <site name="T_thtip_tip" type="sphere" group="5" pos="0 0 0.026" size="0.01"
                                              rgba="1 1 0 0"/>
                                    </body>
                                </body>
                            </body>
                        </body>
                    </body>
                </body>
            </body>
        </body>
    </worldbody>

    <contact>
        <exclude body1="rh_wrist" body2="rh_forearm"/>
        <exclude body1="rh_thproximal" body2="rh_thmiddle"/>
    </contact>

    <tendon>
        <fixed name="rh_FFJ0">
            <joint joint="rh_FFJ2" coef="1"/>
            <joint joint="rh_FFJ1" coef="1"/>
        </fixed>
        <fixed name="rh_MFJ0">
            <joint joint="rh_MFJ2" coef="1"/>
            <joint joint="rh_MFJ1" coef="1"/>
        </fixed>
        <fixed name="rh_RFJ0">
            <joint joint="rh_RFJ2" coef="1"/>
            <joint joint="rh_RFJ1" coef="1"/>
        </fixed>
        <fixed name="rh_LFJ0">
            <joint joint="rh_LFJ2" coef="1"/>
            <joint joint="rh_LFJ1" coef="1"/>
        </fixed>

        <fixed name="rh_T_WRJ2r" limited="true" range="-0.032 0.032" user="1236">
            <joint joint="rh_WRJ2" coef="0.0325"></joint>
        </fixed>
        <fixed name="rh_T_WRJ2l" limited="true" range="-0.032 0.032" user="1237">
            <joint joint="rh_WRJ2" coef="-0.0325"></joint>
        </fixed>
        <fixed name="rh_T_WRJ1u" limited="true" range="-0.032 0.032" user="1236">
            <joint joint="rh_WRJ1" coef="0.0175"></joint>
        </fixed>
        <fixed name="rh_T_WRJ1d" limited="true" range="-0.032 0.032" user="1237">
            <joint joint="rh_WRJ1" coef="-0.0175"></joint>
        </fixed>
        <fixed name="rh_T_FFJ3r" limited="true" range="-0.018 0.018" user="1204">
            <joint joint="rh_FFJ3" coef="0.01"></joint>
        </fixed>
        <fixed name="rh_T_FFJ3l" limited="true" range="-0.018 0.018" user="1205">
            <joint joint="rh_FFJ3" coef="-0.01"></joint>
        </fixed>
        <fixed name="rh_T_FFJ2u" limited="true" range="-0.007 0.03" user="1202">
            <joint joint="rh_FFJ2" coef="0.01"></joint>
        </fixed>
        <fixed name="rh_T_FFJ2d" limited="true" range="-0.03 0.007" user="1203">
            <joint joint="rh_FFJ2" coef="-0.01"></joint>
        </fixed>
        <fixed name="rh_T_MFJ3r" limited="true" range="-0.018 0.018" user="1210">
            <joint joint="rh_MFJ3" coef="0.01"></joint>
        </fixed>
        <fixed name="rh_T_MFJ3l" limited="true" range="-0.018 0.018" user="1211">
            <joint joint="rh_MFJ3" coef="-0.01"></joint>
        </fixed>
        <fixed name="rh_T_MFJ2u" limited="true" range="-0.007 0.03" user="1208">
            <joint joint="rh_MFJ2" coef="0.01"></joint>
        </fixed>
        <fixed name="rh_T_MFJ2d" limited="true" range="-0.03 0.007" user="1209">
            <joint joint="rh_MFJ2" coef="-0.01"></joint>
        </fixed>
        <fixed name="rh_T_RFJ3r" limited="true" range="-0.018 0.018" user="1216">
            <joint joint="rh_RFJ3" coef="0.01"></joint>
        </fixed>
        <fixed name="rh_T_RFJ3l" limited="true" range="-0.018 0.018" user="1217">
            <joint joint="rh_RFJ3" coef="-0.01"></joint>
        </fixed>
        <fixed name="rh_T_RFJ2u" limited="true" range="-0.007 0.03" user="1214">
            <joint joint="rh_RFJ2" coef="0.01"></joint>
        </fixed>
        <fixed name="rh_T_RFJ2d" limited="true" range="-0.03 0.007" user="1215">
            <joint joint="rh_RFJ2" coef="-0.01"></joint>
        </fixed>
        <fixed name="rh_T_LFJ4u" limited="true" range="-0.007 0.03" user="1224">
            <joint joint="rh_LFJ4" coef="0.01"></joint>
        </fixed>
        <fixed name="rh_T_LFJ4d" limited="true" range="-0.03 0.007" user="1225">
            <joint joint="rh_LFJ4" coef="-0.01"></joint>
        </fixed>
        <fixed name="rh_T_LFJ3r" limited="true" range="-0.018 0.018" user="1222">
            <joint joint="rh_LFJ3" coef="0.01"></joint>
        </fixed>
        <fixed name="rh_T_LFJ3l" limited="true" range="-0.018 0.018" user="1223">
            <joint joint="rh_LFJ3" coef="-0.01"></joint>
        </fixed>
        <fixed name="rh_T_LFJ2u" limited="true" range="-0.007 0.03" user="1220">
            <joint joint="rh_LFJ2" coef="0.01"></joint>
        </fixed>
        <fixed name="rh_T_LFJ2d" limited="true" range="-0.03 0.007" user="1221">
            <joint joint="rh_LFJ2" coef="-0.01"></joint>
        </fixed>
        <fixed name="rh_T_THJ5a" limited="true" range="-0.018 0.018" user="1234">
            <joint joint="rh_THJ5" coef="0.01636"></joint>
        </fixed>
        <fixed name="rh_T_THJ5c" limited="true" range="-0.018 0.018" user="1235">
            <joint joint="rh_THJ5" coef="-0.01636"></joint>
        </fixed>
        <fixed name="rh_T_THJ4u" limited="true" range="-0.007 0.03" user="1232">
            <joint joint="rh_THJ4" coef="0.01"></joint>
        </fixed>
        <fixed name="rh_T_THJ4d" limited="true" range="-0.03 0.007" user="1233">
            <joint joint="rh_THJ4" coef="-0.01"></joint>
        </fixed>
        <fixed name="rh_T_THJ3u" limited="true" range="-0.018 0.018" user="1230">
            <joint joint="rh_THJ3" coef="0.011"></joint>
        </fixed>
        <fixed name="rh_T_THJ3d" limited="true" range="-0.018 0.018" user="1231">
            <joint joint="rh_THJ3" coef="-0.011"></joint>
        </fixed>
        <fixed name="rh_T_THJ2r" limited="true" range="-0.018 0.018" user="1228">
            <joint joint="rh_THJ2" coef="0.011"></joint>
        </fixed>
        <fixed name="rh_T_THJ2l" limited="true" range="-0.018 0.018" user="1229">
            <joint joint="rh_THJ2" coef="-0.011"></joint>
        </fixed>
        <fixed name="rh_T_THJ1r" limited="true" range="-0.03 0.007" user="1226">
            <joint joint="rh_THJ1" coef="0.009"></joint>
        </fixed>
        <fixed name="rh_T_THJ1l" limited="true" range="-0.007 0.03" user="1227">
            <joint joint="rh_THJ1" coef="-0.009"></joint>
        </fixed>
    </tendon>

    <actuator>
        <position name="rh_A_WRJ2" joint="rh_WRJ2" class="wrist_y"/>
        <position name="rh_A_WRJ1" joint="rh_WRJ1" class="wrist_x"/>
        <position name="rh_A_THJ5" joint="rh_THJ5" class="thbase"/>
        <position name="rh_A_THJ4" joint="rh_THJ4" class="thproximal"/>
        <position name="rh_A_THJ3" joint="rh_THJ3" class="thhub"/>
        <position name="rh_A_THJ2" joint="rh_THJ2" class="thmiddle"/>
        <position name="rh_A_THJ1" joint="rh_THJ1" class="thdistal"/>
        <position name="rh_A_FFJ4" joint="rh_FFJ4" class="knuckle"/>
        <position name="rh_A_FFJ3" joint="rh_FFJ3" class="proximal"/>
        <position name="rh_A_FFJ0" tendon="rh_FFJ0" class="middle_distal"/>
        <position name="rh_A_MFJ4" joint="rh_MFJ4" class="knuckle"/>
        <position name="rh_A_MFJ3" joint="rh_MFJ3" class="proximal"/>
        <position name="rh_A_MFJ0" tendon="rh_MFJ0" class="middle_distal"/>
        <position name="rh_A_RFJ4" joint="rh_RFJ4" class="knuckle"/>
        <position name="rh_A_RFJ3" joint="rh_RFJ3" class="proximal"/>
        <position name="rh_A_RFJ0" tendon="rh_RFJ0" class="middle_distal"/>
        <position name="rh_A_LFJ5" joint="rh_LFJ5" class="metacarpal"/>
        <position name="rh_A_LFJ4" joint="rh_LFJ4" class="knuckle"/>
        <position name="rh_A_LFJ3" joint="rh_LFJ3" class="proximal"/>
        <position name="rh_A_LFJ0" tendon="rh_LFJ0" class="middle_distal"/>
    </actuator>

    <sensor>
        <!--PALM-->
        <touch name="rh_TS_palm_b0" site="T_palm_b0"/>
        <touch name="rh_TS_palm_bl" site="T_palm_bl"/>
        <touch name="rh_TS_palm_bm" site="T_palm_bm"/>
        <touch name="rh_TS_palm_br" site="T_palm_br"/>
        <touch name="rh_TS_palm_fl" site="T_palm_fl"/>
        <touch name="rh_TS_palm_fm" site="T_palm_fm"/>
        <touch name="rh_TS_palm_fr" site="T_palm_fr"/>
        <touch name="rh_TS_palm_b1" site="T_palm_b1"/>

        <!--FOREFINGER-->
        <touch name="rh_TS_ffproximal_front_left_bottom" site="T_ffproximal_front_left_bottom"/>
        <touch name="rh_TS_ffproximal_front_right_bottom" site="T_ffproximal_front_right_bottom"/>
        <touch name="rh_TS_ffproximal_front_left_top" site="T_ffproximal_front_left_top"/>
        <touch name="rh_TS_ffproximal_front_right_top" site="T_ffproximal_front_right_top"/>
        <touch name="rh_TS_ffproximal_back_left" site="T_ffproximal_back_left"/>
        <touch name="rh_TS_ffproximal_back_right" site="T_ffproximal_back_right"/>
        <touch name="rh_TS_ffproximal_tip" site="T_ffproximal_tip"/>

        <touch name="rh_TS_ffmiddle_front_left" site="T_ffmiddle_front_left"/>
        <touch name="rh_TS_ffmiddle_front_right" site="T_ffmiddle_front_right"/>
        <touch name="rh_TS_ffmiddle_back_left" site="T_ffmiddle_back_left"/>
        <touch name="rh_TS_ffmiddle_back_right" site="T_ffmiddle_back_right"/>
        <touch name="rh_TS_ffmiddle_tip" site="T_ffmiddle_tip"/>

        <touch name="rh_TS_fftip_front_left" site="T_fftip_front_left"/>
        <touch name="rh_TS_fftip_front_right" site="T_fftip_front_right"/>
        <touch name="rh_TS_fftip_back_left" site="T_fftip_back_left"/>
        <touch name="rh_TS_fftip_back_right" site="T_fftip_back_right"/>
        <touch name="rh_TS_fftip_tip" site="T_fftip_tip"/>

        <!-- MIDDLE FINGER -->
        <touch name="rh_TS_mfproximal_front_left_bottom" site="T_mfproximal_front_left_bottom"/>
        <touch name="rh_TS_mfproximal_front_right_bottom" site="T_mfproximal_front_right_bottom"/>
        <touch name="rh_TS_mfproximal_front_left_top" site="T_mfproximal_front_left_top"/>
        <touch name="rh_TS_mfproximal_front_right_top" site="T_mfproximal_front_right_top"/>
        <touch name="rh_TS_mfproximal_back_left" site="T_mfproximal_back_left"/>
        <touch name="rh_TS_mfproximal_back_right" site="T_mfproximal_back_right"/>
        <touch name="rh_TS_mfproximal_tip" site="T_mfproximal_tip"/>

        <touch name="rh_TS_mfmiddle_front_left" site="T_mfmiddle_front_left"/>
        <touch name="rh_TS_mfmiddle_front_right" site="T_mfmiddle_front_right"/>
        <touch name="rh_TS_mfmiddle_back_left" site="T_mfmiddle_back_left"/>
        <touch name="rh_TS_mfmiddle_back_right" site="T_mfmiddle_back_right"/>
        <touch name="rh_TS_mfmiddle_tip" site="T_mfmiddle_tip"/>

        <touch name="rh_TS_mftip_front_left" site="T_mftip_front_left"/>
        <touch name="rh_TS_mftip_front_right" site="T_mftip_front_right"/>
        <touch name="rh_TS_mftip_back_left" site="T_mftip_back_left"/>
        <touch name="rh_TS_mftip_back_right" site="T_mftip_back_right"/>
        <touch name="rh_TS_mftip_tip" site="T_mftip_tip"/>

        <!-- RING FINGER -->
        <touch name="rh_TS_rfproximal_front_left_bottom" site="T_rfproximal_front_left_bottom"/>
        <touch name="rh_TS_rfproximal_front_right_bottom" site="T_rfproximal_front_right_bottom"/>
        <touch name="rh_TS_rfproximal_front_left_top" site="T_rfproximal_front_left_top"/>
        <touch name="rh_TS_rfproximal_front_right_top" site="T_rfproximal_front_right_top"/>
        <touch name="rh_TS_rfproximal_back_left" site="T_rfproximal_back_left"/>
        <touch name="rh_TS_rfproximal_back_right" site="T_rfproximal_back_right"/>
        <touch name="rh_TS_rfproximal_tip" site="T_rfproximal_tip"/>

        <touch name="rh_TS_rfmiddle_front_left" site="T_rfmiddle_front_left"/>
        <touch name="rh_TS_rfmiddle_front_right" site="T_rfmiddle_front_right"/>
        <touch name="rh_TS_rfmiddle_back_left" site="T_rfmiddle_back_left"/>
        <touch name="rh_TS_rfmiddle_back_right" site="T_rfmiddle_back_right"/>
        <touch name="rh_TS_rfmiddle_tip" site="T_rfmiddle_tip"/>

        <touch name="rh_TS_rftip_front_left" site="T_rftip_front_left"/>
        <touch name="rh_TS_rftip_front_right" site="T_rftip_front_right"/>
        <touch name="rh_TS_rftip_back_left" site="T_rftip_back_left"/>
        <touch name="rh_TS_rftip_back_right" site="T_rftip_back_right"/>
        <touch name="rh_TS_rftip_tip" site="T_rftip_tip"/>

        <!-- LITTLE FINGER -->
        <touch name="rh_TS_lfmetacarpal_front" site="T_lfmetacarpal_front"/>

        <touch name="rh_TS_lfproximal_front_left_bottom" site="T_lfproximal_front_left_bottom"/>
        <touch name="rh_TS_lfproximal_front_right_bottom" site="T_lfproximal_front_right_bottom"/>
        <touch name="rh_TS_lfproximal_front_left_top" site="T_lfproximal_front_left_top"/>
        <touch name="rh_TS_lfproximal_front_right_top" site="T_lfproximal_front_right_top"/>
        <touch name="rh_TS_lfproximal_back_left" site="T_lfproximal_back_left"/>
        <touch name="rh_TS_lfproximal_back_right" site="T_lfproximal_back_right"/>
        <touch name="rh_TS_lfproximal_tip" site="T_lfproximal_tip"/>

        <touch name="rh_TS_lfmiddle_front_left" site="T_lfmiddle_front_left"/>
        <touch name="rh_TS_lfmiddle_front_right" site="T_lfmiddle_front_right"/>
        <touch name="rh_TS_lfmiddle_back_left" site="T_lfmiddle_back_left"/>
        <touch name="rh_TS_lfmiddle_back_right" site="T_lfmiddle_back_right"/>
        <touch name="rh_TS_lfmiddle_tip" site="T_lfmiddle_tip"/>

        <touch name="rh_TS_lftip_front_left" site="T_lftip_front_left"/>
        <touch name="rh_TS_lftip_front_right" site="T_lftip_front_right"/>
        <touch name="rh_TS_lftip_back_left" site="T_lftip_back_left"/>
        <touch name="rh_TS_lftip_back_right" site="T_lftip_back_right"/>
        <touch name="rh_TS_lftip_tip" site="T_lftip_tip"/>

        <!--THUMB-->
        <touch name="rh_TS_thproximal_front_left" site="T_thproximal_front_left"/>
        <touch name="rh_TS_thproximal_front_right" site="T_thproximal_front_right"/>
        <touch name="rh_TS_thproximal_back_left" site="T_thproximal_back_left"/>
        <touch name="rh_TS_thproximal_back_right" site="T_thproximal_back_right"/>
        <touch name="rh_TS_thproximal_tip" site="T_thproximal_tip"/>

        <touch name="rh_TS_thmiddle_front_left" site="T_thmiddle_front_left"/>
        <touch name="rh_TS_thmiddle_front_right" site="T_thmiddle_front_right"/>
        <touch name="rh_TS_thmiddle_back_left" site="T_thmiddle_back_left"/>
        <touch name="rh_TS_thmiddle_back_right" site="T_thmiddle_back_right"/>
        <touch name="rh_TS_thmiddle_tip" site="T_thmiddle_tip"/>

        <touch name="rh_TS_thtip_front_left" site="T_thtip_front_left"/>
        <touch name="rh_TS_thtip_front_right" site="T_thtip_front_right"/>
        <touch name="rh_TS_thtip_back_left" site="T_thtip_back_left"/>
        <touch name="rh_TS_thtip_back_right" site="T_thtip_back_right"/>
        <touch name="rh_TS_thtip_tip" site="T_thtip_tip"/>

    </sensor>

</mujoco>
